<?xml version="1.0"?>
<sdf version="1.4">

    <model name="conveyor_belt">

        <model name="conveyorbelt_fixed">

            <static>true</static>

            <link name="belt_visual">
                <visual name="visual">
                    <geometry>
                        <mesh>
                            <scale>1 1 1</scale>
                            <uri>model://conveyor_belt_1/meshes/conveyor_belt.dae</uri>
                        </mesh>
                    </geometry>
                </visual>
                <collision name="collision">
                    <origin xyz="0.0 0.0 0" rpy="0.0 0.0 0.0" />
                    <geometry>
                        <mesh>
                            <scale>1 1 1</scale>
                            <uri>model://conveyor_belt_1/meshes/conveyor_belt.dae</uri>
                        </mesh>
                    </geometry>
                </collision>
            </link>

            <link name="camera_link">
                <pose>0 -0.3 1 0 1.57 0</pose> <!-- Ajuste a posição e orientação conforme necessário -->

                <sensor name="camera_sensor" type="camera">
                    <camera>
                        <horizontal_fov>1.3962634</horizontal_fov>
                        <image>
                            <width>800</width>
                            <height>600</height>
                        </image>
                        <clip>
                            <near>0.01</near>
                            <far>100</far>
                        </clip>
                    </camera>

                    <always_on>1</always_on>
                    <update_rate>30</update_rate>
                    <visualize>true</visualize>

                    <plugin name="camera_controller" filename="libgazebo_ros_camera.so">
                        <namespace>b3</namespace>
                    </plugin>

                </sensor>
            </link>
        </model>

        <model name="conveyorbelt_moving">

            <allow_auto_disable>0</allow_auto_disable>
            <static>false</static>

            <pose>0 0 0.741 0 0 0.0</pose>

            <link name="belt_moving">
                <inertial>
                    <mass>100.0</mass>
                    <inertia>
                        <ixx>0.0</ixx>
                        <ixy>0.0</ixy>
                        <ixz>0.0</ixz>
                        <iyy>0.0</iyy>
                        <iyz>0.0</iyz>
                        <izz>0.0</izz>
                    </inertia>
                </inertial>
                <collision name="belt_collision">
                    <geometry>
                        <box>
                            <size>0.425 1.2 0.00001</size>
                        </box>
                    </geometry>
                    <surface>
                        <friction>
                            <ode>
                                <mu>100.0</mu>
                                <mu2>100.0</mu2>
                            </ode>
                            <torsional>
                                <coefficient>1000.0</coefficient>
                                <patch_radius>0.1</patch_radius>
                            </torsional>
                        </friction>
                    </surface>
                </collision>
                <!--
                <visual name="belt_visual">
                    <geometry>
                        <box>
                            <size>0.425 1.2 0.001</size>
                        </box>
                    </geometry>
                </visual>
                -->
            </link>

        </model>

        <joint name="belt_joint" type="prismatic">
            <parent>conveyorbelt_fixed::belt_visual</parent>
            <child>conveyorbelt_moving::belt_moving</child>
            <axis>
                <xyz>0 1 0</xyz>
                <limit>
                    <lower>0.0</lower>
                    <upper>0.01</upper>
                </limit>
            </axis>
        </joint>

        <link name="box_of_cork_visual">
            <pose>0 0.01 0 0 0 0</pose>
            <visual name="box_visual">
                <geometry>
                    <mesh>
                        <scale>1 1 1</scale>
                        <uri>model://box_of_cork/meshes/box_of_cork.dae</uri>
                    </mesh>
                </geometry>
            </visual>
            <collision name="collision">
                <origin xyz="0.0 0.0 0" rpy="0.0 0.0 0.0" />
                <geometry>
                    <mesh>
                        <scale>1 1 1</scale>
                        <uri>model://box_of_cork/meshes/box_of_cork.dae</uri>
                    </mesh>
                </geometry>
            </collision>
        </link>

        <joint name="fixed_joint" type="fixed">
            <parent>conveyorbelt_fixed::belt_visual</parent>
            <child>box_of_cork_visual</child>
        </joint>
    </model>


</sdf>